<?xml version="1.0" encoding="utf-8"?>
<!-- This URDF was automatically created by SolidWorks to URDF Exporter! Originally created by Stephen Brawner (brawner@gmail.com) 
     Commit Version: 1.5.1-0-g916b5db  Build Version: 1.5.7152.31018
     For more information, please see http://wiki.ros.org/sw_urdf_exporter -->
<robot
  name="lide">
  <link
    name="base_link">
    <inertial>
      <origin
        xyz="-0.124039089703059 0.0849018285649875 0.0507049336382351"
        rpy="0 0 0" />
      <mass
        value="2.91745388040908" />
      <inertia
        ixx="0.00617452431631895"
        ixy="-7.1545090527461E-07"
        ixz="-1.26679487712579E-05"
        iyy="0.00553460681657008"
        iyz="-3.51329121715537E-07"
        izz="0.0110508759807573" />
    </inertial>
    <visual>
      <origin
        xyz="0 0 0"
        rpy="0 0 0" />
      <geometry>
        <mesh
          filename="package://lide/meshes/base_link.STL" />
      </geometry>
      <material
        name="">
        <color
          rgba="0.752941176470588 0.752941176470588 0.752941176470588 1" />
      </material>
    </visual>
    <collision>
      <origin
        xyz="0 0 0"
        rpy="0 0 0" />
      <geometry>
        <mesh
          filename="package://lide/meshes/base_link.STL" />
      </geometry>
    </collision>
  </link>
  <link
    name="LFS">
    <inertial>
      <origin
        xyz="0.0455604268709419 0.00830943309140331 0.00297622851896683"
        rpy="0 0 0" />
      <mass
        value="0.0727928435161986" />
      <inertia
        ixx="2.20927876796312E-05"
        ixy="-1.6484530205639E-08"
        ixz="-1.56454773175215E-07"
        iyy="1.62632133784213E-05"
        iyz="2.96411876511182E-09"
        izz="1.80843397531752E-05" />
    </inertial>
    <visual>
      <origin
        xyz="0 0 0"
        rpy="0 0 0" />
      <geometry>
        <mesh
          filename="package://lide/meshes/LFS.STL" />
      </geometry>
      <material
        name="">
        <color
          rgba="0.752941176470588 0.752941176470588 0.752941176470588 1" />
      </material>
    </visual>
    <collision>
      <origin
        xyz="0 0 0"
        rpy="0 0 0" />
      <geometry>
        <mesh
          filename="package://lide/meshes/LFS.STL" />
      </geometry>
    </collision>
  </link>
  <joint
    name="LFS"
    type="fixed">
    <origin
      xyz="-0.054044 0.18241 -0.036503"
      rpy="1.5708 0 1.5708" />
    <parent
      link="base_link" />
    <child
      link="LFS" />
    <axis
      xyz="0 0 0" />
  </joint>
  <link
    name="LFW">
    <inertial>
      <origin
        xyz="0.015 0 3.46944695195361E-18"
        rpy="0 0 0" />
      <mass
        value="0.767080911081153" />
      <inertia
        ixx="0.00116426102407189"
        ixy="4.45758864315272E-22"
        ixz="-1.82994146746971E-20"
        iyy="0.000639661580367031"
        iyz="-1.35525271560688E-20"
        izz="0.000639661580367032" />
    </inertial>
    <visual>
      <origin
        xyz="0 0 0"
        rpy="0 0 0" />
      <geometry>
        <mesh
          filename="package://lide/meshes/LFW.STL" />
      </geometry>
      <material
        name="">
        <color
          rgba="0.898039215686275 0.917647058823529 0.929411764705882 1" />
      </material>
    </visual>
    <collision>
      <origin
        xyz="0 0 0"
        rpy="0 0 0" />
      <geometry>
        <mesh
          filename="package://lide/meshes/LFW.STL" />
      </geometry>
    </collision>
  </link>
  <joint
    name="LFW"
    type="continuous">
    <origin
      xyz="0.0633463599631527 -0.00679803845222953 0.0150436140506676"
      rpy="-1.62639053095063 0 0" />
    <parent
      link="LFS" />
    <child
      link="LFW" />
    <axis
      xyz="1 0 0" />
    <limit
      effort="3.1"
      velocity="7" />
  </joint>
  <link
    name="RFS">
    <inertial>
      <origin
        xyz="-0.0191828308457407 -0.00900932874707057 0.0520056318885905"
        rpy="0 0 0" />
      <mass
        value="0.0727928435161986" />
      <inertia
        ixx="2.20927876796313E-05"
        ixy="-1.64845302056319E-08"
        ixz="1.56454773175213E-07"
        iyy="1.62632133784213E-05"
        iyz="-2.96411876510421E-09"
        izz="1.80843397531752E-05" />
    </inertial>
    <visual>
      <origin
        xyz="0 0 0"
        rpy="0 0 0" />
      <geometry>
        <mesh
          filename="package://lide/meshes/RFS.STL" />
      </geometry>
      <material
        name="">
        <color
          rgba="0.752941176470588 0.752941176470588 0.752941176470588 1" />
      </material>
    </visual>
    <collision>
      <origin
        xyz="0 0 0"
        rpy="0 0 0" />
      <geometry>
        <mesh
          filename="package://lide/meshes/RFS.STL" />
      </geometry>
    </collision>
  </link>
  <joint
    name="RFS"
    type="fixed">
    <origin
      xyz="-0.10307 -0.042784 -0.019216"
      rpy="1.5708 0 1.5708" />
    <parent
      link="base_link" />
    <child
      link="RFS" />
    <axis
      xyz="0 0 0" />
  </joint>
  <link
    name="RFW">
    <inertial>
      <origin
        xyz="-0.015 0 0"
        rpy="0 0 0" />
      <mass
        value="0.767080911081152" />
      <inertia
        ixx="0.00116426102407189"
        ixy="-1.2315168370675E-36"
        ixz="4.60638074444741E-39"
        iyy="0.000639661580367031"
        iyz="8.00462841683581E-39"
        izz="0.000639661580367031" />
    </inertial>
    <visual>
      <origin
        xyz="0 0 0"
        rpy="0 0 0" />
      <geometry>
        <mesh
          filename="package://lide/meshes/RFW.STL" />
      </geometry>
      <material
        name="">
        <color
          rgba="0.898039215686275 0.917647058823529 0.929411764705882 1" />
      </material>
    </visual>
    <collision>
      <origin
        xyz="0 0 0"
        rpy="0 0 0" />
      <geometry>
        <mesh
          filename="package://lide/meshes/RFW.STL" />
      </geometry>
    </collision>
  </link>
  <joint
    name="RFW"
    type="continuous">
    <origin
      xyz="-0.036969 -0.024084 0.064073"
      rpy="0 0 0" />
    <parent
      link="RFS" />
    <child
      link="RFW" />
    <axis
      xyz="1 0 0" />
    <limit
      effort="3.1"
      velocity="7" />
  </joint>
  <link
    name="LBS">
    <inertial>
      <origin
        xyz="0 -0.029384279339137 0"
        rpy="0 0 0" />
      <mass
        value="0.0953719735550794" />
      <inertia
        ixx="8.60551274221477E-05"
        ixy="8.25033890435269E-22"
        ixz="5.70072799361511E-20"
        iyy="8.19515157071385E-05"
        iyz="-2.7466330021711E-20"
        izz="8.63158418017919E-05" />
    </inertial>
    <visual>
      <origin
        xyz="0 0 0"
        rpy="0 0 0" />
      <geometry>
        <mesh
          filename="package://lide/meshes/LBS.STL" />
      </geometry>
      <material
        name="">
        <color
          rgba="0.898039215686275 0.917647058823529 0.929411764705882 1" />
      </material>
    </visual>
    <collision>
      <origin
        xyz="0 0 0"
        rpy="0 0 0" />
      <geometry>
        <mesh
          filename="package://lide/meshes/LBS.STL" />
      </geometry>
    </collision>
  </link>
  <joint
    name="LBS"
    type="fixed">
    <origin
      xyz="-0.202 0.228 -0.0025623"
      rpy="1.5708 0 1.5708" />
    <parent
      link="base_link" />
    <child
      link="LBS" />
    <axis
      xyz="0 0 0" />
  </joint>
  <link
    name="LBW">
    <inertial>
      <origin
        xyz="6.9389E-18 0 -2.7756E-17"
        rpy="0 0 0" />
      <mass
        value="0.47957" />
      <inertia
        ixx="0.00023542"
        ixy="-1.9655E-38"
        ixz="7.7646E-40"
        iyy="0.00023758"
        iyz="-7.8066E-40"
        izz="0.00023542" />
    </inertial>
    <visual>
      <origin
        xyz="0 0 0"
        rpy="0 0 0" />
      <geometry>
        <mesh
          filename="package://lide/meshes/LBW.STL" />
      </geometry>
      <material
        name="">
        <color
          rgba="0.89804 0.91765 0.92941 1" />
      </material>
    </visual>
    <collision>
      <origin
        xyz="0 0 0"
        rpy="0 0 0" />
      <geometry>
        <mesh
          filename="package://lide/meshes/LBW.STL" />
      </geometry>
    </collision>
  </link>
  <joint
    name="LBW"
    type="revolute">
    <origin
      xyz="0 -0.060738 0"
      rpy="0 0 -1.5708" />
    <parent
      link="LBS" />
    <child
      link="LBW" />
    <axis
      xyz="0 1 0" />
    <limit
      lower="0"
      upper="0"
      effort="0"
      velocity="0" />
    <dynamics
      damping="0.001" />
  </joint>
  <link
    name="RBS">
    <inertial>
      <origin
        xyz="0 -0.029384279339137 -2.77555756156289E-17"
        rpy="0 0 0" />
      <mass
        value="0.0953719735550794" />
      <inertia
        ixx="8.60551274221477E-05"
        ixy="4.83996477136411E-20"
        ixz="5.96249293805221E-20"
        iyy="8.19515157071387E-05"
        iyz="-2.7466330021711E-20"
        izz="8.63158418017921E-05" />
    </inertial>
    <visual>
      <origin
        xyz="0 0 0"
        rpy="0 0 0" />
      <geometry>
        <mesh
          filename="package://lide/meshes/RBS.STL" />
      </geometry>
      <material
        name="">
        <color
          rgba="0.898039215686275 0.917647058823529 0.929411764705882 1" />
      </material>
    </visual>
    <collision>
      <origin
        xyz="0 0 0"
        rpy="0 0 0" />
      <geometry>
        <mesh
          filename="package://lide/meshes/RBS.STL" />
      </geometry>
    </collision>
  </link>
  <joint
    name="RBS"
    type="fixed">
    <origin
      xyz="-0.202 -0.062003 -0.0025623"
      rpy="1.5708 0 1.5708" />
    <parent
      link="base_link" />
    <child
      link="RBS" />
    <axis
      xyz="0 0 0" />
  </joint>
  <link
    name="RBW">
    <inertial>
      <origin
        xyz="0 0 0"
        rpy="0 0 0" />
      <mass
        value="0.47957" />
      <inertia
        ixx="0.00023542"
        ixy="7.2576E-39"
        ixz="3.4442E-40"
        iyy="0.00023758"
        iyz="-7.6906E-40"
        izz="0.00023542" />
    </inertial>
    <visual>
      <origin
        xyz="0 0 0"
        rpy="0 0 0" />
      <geometry>
        <mesh
          filename="package://lide/meshes/RBW.STL" />
      </geometry>
      <material
        name="">
        <color
          rgba="0.89804 0.91765 0.92941 1" />
      </material>
    </visual>
    <collision>
      <origin
        xyz="0 0 0"
        rpy="0 0 0" />
      <geometry>
        <mesh
          filename="package://lide/meshes/RBW.STL" />
      </geometry>
    </collision>
  </link>
  <joint
    name="RBW"
    type="revolute">
    <origin
      xyz="0 -0.060738 0"
      rpy="0 0 -1.5708" />
    <parent
      link="RBS" />
    <child
      link="RBW" />
    <axis
      xyz="0 1 0" />
    <limit
      lower="0"
      upper="0"
      effort="0"
      velocity="0" />
    <dynamics
      damping="0.001" />
  </joint>
  <link
    name="fcam">
    <inertial>
      <origin
        xyz="-0.0115544746517359 -2.64429642850283E-06 0.00129029302682174"
        rpy="0 0 0" />
      <mass
        value="0.0436119957238952" />
      <inertia
        ixx="2.35707061906175E-05"
        ixy="-1.01842273865681E-09"
        ixz="2.17585832536658E-08"
        iyy="4.29479050056035E-06"
        iyz="-8.85018118759863E-10"
        izz="2.21058153511886E-05" />
    </inertial>
    <visual>
      <origin
        xyz="0 0 0"
        rpy="0 0 0" />
      <geometry>
        <mesh
          filename="package://lide/meshes/fcam.STL" />
      </geometry>
      <material
        name="">
        <color
          rgba="0.792156862745098 0.819607843137255 0.933333333333333 1" />
      </material>
    </visual>
    <collision>
      <origin
        xyz="0 0 0"
        rpy="0 0 0" />
      <geometry>
        <mesh
          filename="package://lide/meshes/fcam.STL" />
      </geometry>
    </collision>
  </link>
  <joint
    name="fcam"
    type="fixed">
    <origin
      xyz="-0.0038823 0.083 0.12982"
      rpy="0 0.2618 0" />
    <parent
      link="base_link" />
    <child
      link="fcam" />
    <axis
      xyz="0 0 0" />
  </joint>
  <link
    name="bcam">
    <inertial>
      <origin
        xyz="-0.02010346452991 -2.64354903287134E-06 -0.00725869505663598"
        rpy="0 0 0" />
      <mass
        value="0.0436119949785286" />
      <inertia
        ixx="2.357070560996E-05"
        ixy="-1.01834758005619E-09"
        ixz="2.17579332532706E-08"
        iyy="4.29479078276665E-06"
        iyz="-8.85484503961915E-10"
        izz="2.21058144654638E-05" />
    </inertial>
    <visual>
      <origin
        xyz="0 0 0"
        rpy="0 0 0" />
      <geometry>
        <mesh
          filename="package://lide/meshes/bcam.STL" />
      </geometry>
      <material
        name="">
        <color
          rgba="0.792156862745098 0.819607843137255 0.933333333333333 1" />
      </material>
    </visual>
    <collision>
      <origin
        xyz="0 0 0"
        rpy="0 0 0" />
      <geometry>
        <mesh
          filename="package://lide/meshes/bcam.STL" />
      </geometry>
    </collision>
  </link>
  <joint
    name="bcam"
    type="fixed">
    <origin
      xyz="0 0.083 0.091232"
      rpy="0 0.7854 0" />
    <parent
      link="base_link" />
    <child
      link="bcam" />
    <axis
      xyz="0 0 0" />
  </joint>
  <link
    name="Lidar">
    <inertial>
      <origin
        xyz="0.0135233595886408 0.000461955982206302 -0.0287648854950511"
        rpy="0 0 0" />
      <mass
        value="0.0730845717569496" />
      <inertia
        ixx="1.95808757419765E-05"
        ixy="-1.03933585736234E-07"
        ixz="-4.28391168396098E-07"
        iyy="2.41250079666672E-05"
        iyz="9.42710206434151E-09"
        izz="4.14184516368183E-05" />
    </inertial>
    <visual>
      <origin
        xyz="0 0 0"
        rpy="0 0 0" />
      <geometry>
        <mesh
          filename="package://lide/meshes/Lidar.STL" />
      </geometry>
      <material
        name="">
        <color
          rgba="0.792156862745098 0.819607843137255 0.933333333333333 1" />
      </material>
    </visual>
    <collision>
      <origin
        xyz="0 0 0"
        rpy="0 0 0" />
      <geometry>
        <mesh
          filename="package://lide/meshes/Lidar.STL" />
      </geometry>
    </collision>
  </link>
  <joint
    name="Lidar"
    type="fixed">
    <origin
      xyz="-0.19458 0.082006 0.2065"
      rpy="0 0 0" />
    <parent
      link="base_link" />
    <child
      link="Lidar" />
    <axis
      xyz="0 0 0" />
  </joint>
  <link
    name="bacam">
    <inertial>
      <origin
        xyz="-0.011554 -2.6441E-06 0.0012903"
        rpy="0 0 0" />
      <mass
        value="0.043612" />
      <inertia
        ixx="2.3571E-05"
        ixy="-1.0185E-09"
        ixz="2.1758E-08"
        iyy="4.2948E-06"
        iyz="-8.8503E-10"
        izz="2.2106E-05" />
    </inertial>
    <visual>
      <origin
        xyz="0 0 0"
        rpy="0 0 0" />
      <geometry>
        <mesh
          filename="package://lide/meshes/bacam.STL" />
      </geometry>
      <material
        name="">
        <color
          rgba="0.79216 0.81961 0.93333 1" />
      </material>
    </visual>
    <collision>
      <origin
        xyz="0 0 0"
        rpy="0 0 0" />
      <geometry>
        <mesh
          filename="package://lide/meshes/bacam.STL" />
      </geometry>
    </collision>
  </link>
  <joint
    name="bacam"
    type="fixed">
    <origin
      xyz="-0.24887 0.083 0.12838"
      rpy="0 0.34907 3.1416" />
    <parent
      link="base_link" />
    <child
      link="bacam" />
    <axis
      xyz="0 0 0" />
  </joint>
  <link
    name="imu_link">
    <inertial>
      <origin
        xyz="0 0 0"
        rpy="0 0 0" />
      <mass
        value="0" />
      <inertia
        ixx="0"
        ixy="0"
        ixz="0"
        iyy="0"
        iyz="0"
        izz="0" />
    </inertial>
    <visual>
      <origin
        xyz="0 0 0"
        rpy="0 0 0" />
      <geometry>
        <mesh
          filename="package://lide/meshes/imu_link.STL" />
      </geometry>
      <material
        name="">
        <color
          rgba="1 1 1 1" />
      </material>
    </visual>
    <collision>
      <origin
        xyz="0 0 0"
        rpy="0 0 0" />
      <geometry>
        <mesh
          filename="package://lide/meshes/imu_link.STL" />
      </geometry>
    </collision>
  </link>
  <joint
    name="imu_link"
    type="fixed">
    <origin
      xyz="-0.039 0.083 0.155"
      rpy="0 0 0" />
    <parent
      link="base_link" />
    <child
      link="imu_link" />
    <axis
      xyz="0 0 0" />
  </joint>
</robot>